{"errorMessage":"Could not connect to the endpoint URL: \"http://localhost:4566/\"","errorType":"EndpointConnectionError","stackTrace":["  File \"/var/task/flatten_data.py\", line 112, in handler\n    dict_data = convert_data()\n","  File \"/var/task/flatten_data.py\", line 67, in convert_data\n    record = get_record()\n","  File \"/var/task/flatten_data.py\", line 38, in get_record\n    response = client.describe_stream(StreamName=name_stream)\n","  File \"/var/runtime/botocore/client.py\", line 386, in _api_call\n    return self._make_api_call(operation_name, kwargs)\n","  File \"/var/runtime/botocore/client.py\", line 691, in _make_api_call\n    http, parsed_response = self._make_request(\n","  File \"/var/runtime/botocore/client.py\", line 711, in _make_request\n    return self._endpoint.make_request(operation_model, request_dict)\n","  File \"/var/runtime/botocore/endpoint.py\", line 102, in make_request\n    return self._send_request(request_dict, operation_model)\n","  File \"/var/runtime/botocore/endpoint.py\", line 136, in _send_request\n    while self._needs_retry(attempts, operation_model, request_dict,\n","  File \"/var/runtime/botocore/endpoint.py\", line 253, in _needs_retry\n    responses = self._event_emitter.emit(\n","  File \"/var/runtime/botocore/hooks.py\", line 357, in emit\n    return self._emitter.emit(aliased_event_name, **kwargs)\n","  File \"/var/runtime/botocore/hooks.py\", line 228, in emit\n    return self._emit(event_name, kwargs)\n","  File \"/var/runtime/botocore/hooks.py\", line 211, in _emit\n    response = handler(**kwargs)\n","  File \"/var/runtime/botocore/retryhandler.py\", line 183, in __call__\n    if self._checker(attempts, response, caught_exception):\n","  File \"/var/runtime/botocore/retryhandler.py\", line 250, in __call__\n    should_retry = self._should_retry(attempt_number, response,\n","  File \"/var/runtime/botocore/retryhandler.py\", line 277, in _should_retry\n    return self._checker(attempt_number, response, caught_exception)\n","  File \"/var/runtime/botocore/retryhandler.py\", line 316, in __call__\n    checker_response = checker(attempt_number, response,\n","  File \"/var/runtime/botocore/retryhandler.py\", line 222, in __call__\n    return self._check_caught_exception(\n","  File \"/var/runtime/botocore/retryhandler.py\", line 359, in _check_caught_exception\n    raise caught_exception\n","  File \"/var/runtime/botocore/endpoint.py\", line 200, in _do_get_response\n    http_response = self._send(request)\n","  File \"/var/runtime/botocore/endpoint.py\", line 269, in _send\n    return self.http_session.send(request)\n","  File \"/var/runtime/botocore/httpsession.py\", line 373, in send\n    raise EndpointConnectionError(endpoint_url=request.url, error=e)\n"]}
